Workbook

Sheet README
A1: SR2-003 — Sample-Reception LLM: TCO, Sizing, Accuracy & Decision Model
A2: Actlabs · AI Sample Reception (Build) · Generated 2026-07-02 · Companion to the SR2-003 feasibility report
A4: How to use | B4: All blue cells are inputs — edit them on the Assumptions tab and every other tab recalculates. The single biggest unknown is intake volume: the model carries three scenarios (Pilot 100/day, Production 500/day, Scale 2,000/day). Replace them with real numbers when known.
A5: Colour legend | B5: BLUE = hardcoded input you can change · BLACK = formula · GREEN = link to another tab · YELLOW fill = placeholder/assumption needing attention (e.g. Cohere licence, unmeasured accuracy).
A6: Tabs | B6: Assumptions → GPU_Rental → GPU_Sizing → one tab per technology (SelfHost_Llama_8B, SelfHost_Mistral_24B, SelfHost_Llama_70B, Cohere_Private, OCR_AWS_Textract, OCR_GCP_DocAI, OCR_Azure_DI, OCR_SelfHosted) → OCR_LLM_Pipeline → TCO_Summary → Accuracy_SpotCheck → Residency_Compliance → Scoring_Matrix → Recommendation → Pricing_References.
A7: Caveats | B7: GPU throughput = order-of-magnitude vLLM estimates (load-test before capex). Self-hosted accuracy = class-level estimates until the accuracy_spotcheck/ harness is run on lab hardware. Cohere licence is a placeholder. Self-host totals include an MLOps FTE share (25% open / 15% Cohere) — see Assumptions OPS section.

Sheet Assumptions
A1: Assumptions — all model inputs (blue = editable)
A3: VOLUME (single biggest unknown — replace with real intake figures)
A4: Scenario | B4: Forms/day | C4: Docs/year | E4: Note
A5: Pilot | B5: 100 | C5: =B5*$B$8 -> 26000 | E5: No intake figure supplied with SR2-003 — placeholder scenarios
A6: Production | B6: 500 | C6: =B6*$B$8 -> 130000
A7: Scale | B7: 2000 | C7: =B7*$B$8 -> 520000
A8: Working days/year | B8: 260
A10: TOKEN PROFILE PER DOCUMENT
A11: Variable input tokens/doc | B11: 3000 | E11: OCR text of the form
A12: Cacheable input tokens/doc | B12: 3000 | E12: System prompt + 41-field schema — hit by prompt caching
A13: Output tokens/doc | B13: 1500 | E13: Structured JSON, 41 canonical fields
A14: Pages/doc | B14: 3 | E14: Drives OCR per-page cost
A16: SLA / UTILISATION
A17: SLA processing window (hrs/day) | B17: 8
A18: Sustained GPU utilisation | B18: 0.6
A20: INFRA
A21: Capex amortisation (years) | B21: 3
A22: Power cost ($/kWh) | B22: 0.1
A23: PUE (datacentre overhead) | B23: 1.5 | E23: Power Usage Effectiveness, it's a ratio that captures how much extra electricity a data center (or server room) burns beyond what the IT hardware itself consumes.
A24: Hours/year (24×7) | B24: 8760
A27: GPU HARDWARE
A28: GPU | B28: Price ($) | C28: Watts | D28: Rental ($/hr, reserved) | E28: Note
A29: L40S 48GB | B29: 12000 | C29: 350 | D29: 1.8 | E29: Street prices / reserved cloud rates, mid-2026 — verify with vendor quotes
A30: H100 80GB | B30: 32000 | C30: 700 | D30: 2.75
A31: A100 80GB | B31: 20000 | C31: 400 | D31: 2.2
A33: MODEL CONFIGS (self-hosted serving)
A34: Config | B34: GPU row (Assumptions) | C34: # GPUs | D34: Out tok/s (vLLM est.) | E34: Note
A35: Llama-3.1-8B (1× L40S, fp16) | B35: 29 | C35: 1 | D35: 3000 | E35: Throughput = order-of-magnitude batched-serving estimate — load-test before committing capex (±40%)
A36: Mistral-Small-24B (1× H100) | B36: 30 | C36: 1 | D36: 2200
A37: Llama-3.3-70B (1× H100, AWQ 4-bit) | B37: 30 | C37: 1 | D37: 1500
A38: Llama-3.3-70B (2× A100, TP2 fp16) | B38: 31 | C38: 2 | D38: 1200
A39: Cohere Command-A/R+ (4× A100) | B39: 31 | C39: 4 | D39: 900
A41: LICENSING
A42: Cohere private-deployment licence ($/yr) | B42: 150000 | E42: PLACEHOLDER — negotiated per contract, not public. Get a real quote; it dominates the Cohere TCO. In talks with Kyle | F42: https://www.linkedin.com/in/kylepalantzas/
A44: OCR PRICING ($/page)
A45: Provider | B45: $/page | E45: Note
A46: AWS Textract (Forms+Tables/Queries) | B46: 0.065 | E46: Cloud OCR egresses raw documents — breaks a strict data-residency mandate | F46: https://aws.amazon.com/textract/pricing/
A47: GCP Document AI (Form Parser) | B47: 0.03 | F47: https://cloud.google.com/document-ai/pricing
A48: Azure AI Document Intelligence (Layout) | B48: 0.01 | F48: https://azure.microsoft.com/en-us/pricing/details/ai-document-intelligence/
A50: MEASURED BASELINE (SR2-002)
...

Sheet GPU_Rental
A1: Rental GPU providers — quick reference (mid-2026 approx. $/GPU-hr)
A2: Blue = editable rate estimates; rates move weekly — verify on provider pricing pages before budgeting. Annual = rate × hrs/yr (B4).
A4: Hours/year (24×7) | B4: 8760
A6: Provider | B6: Tier | C6: H100 $/hr | D6: A100 $/hr | E6: L40S $/hr | F6: Spot H100 | G6: H100 annual (24×7) | H6: Canada region / notes
A7: AWS | B7: Hyperscaler | C7: 3.9 | D7: 4.1 | E7: — | F7: — | G7: =IF(ISNUMBER(C7),C7*$B$4,"—") -> 34164 | H7: YES (ca-central-1, Montreal). Post-2025 price cuts; egress fees apply
A8: Azure | B8: Hyperscaler | C8: 6.98 | D8: 3.67 | E8: — | F8: — | G8: =IF(ISNUMBER(C8),C8*$B$4,"—") -> 61144.8 | H8: YES (Canada Central, Toronto). Priciest H100 tier
A9: GCP | B9: Hyperscaler | C9: 6.9 | D9: 3.67 | E9: — | F9: — | G9: =IF(ISNUMBER(C9),C9*$B$4,"—") -> 60444 | H9: YES (Montreal/Toronto). A3 instances often 8-GPU minimum
A10: Lambda Labs | B10: Specialist | C10: 2.99 | D10: 1.29 | E10: — | F10: — | G10: =IF(ISNUMBER(C10),C10*$B$4,"—") -> 26192.4 | H10: No CA region. Simple flat pricing, AI-focused
A11: CoreWeave | B11: Specialist | C11: — | D11: — | E11: — | F11: — | G11: =IF(ISNUMBER(C11),C11*$B$4,"—") -> — | H11: Reserved/quote-based; strong for committed capacity
A12: RunPod (Secure) | B12: Specialist | C12: 2.79 | D12: 1.64 | E12: 0.99 | F12: 1.19 | G12: =IF(ISNUMBER(C12),C12*$B$4,"—") -> 24440.4 | H12: Per-second billing; Secure vs cheaper Community tier
A13: Nebius | B13: Specialist | C13: 2.95 | D13: 1.5 | E13: — | F13: — | G13: =IF(ISNUMBER(C13),C13*$B$4,"—") -> 25842 | H13: EU-centric regions
A14: GMI Cloud | B14: Specialist | C14: 2 | D14: — | E14: — | F14: — | G14: =IF(ISNUMBER(C14),C14*$B$4,"—") -> 17520 | H14: $2.00 PCIe / $2.40 SXM; per-minute billing
A15: OVHcloud | B15: Specialist | C15: 2.99 | D15: 2.75 | E15: 1.4 | F15: — | G15: =IF(ISNUMBER(C15),C15*$B$4,"—") -> 26192.4 | H15: YES (Beauharnois, QC datacenter) — Canadian-residency option
A16: Vast.ai | B16: Marketplace | C16: 1.49 | D16: 0.8 | E16: 0.67 | F16: 0.34 | G16: =IF(ISNUMBER(C16),C16*$B$4,"—") -> 13052.4 | H16: Cheapest; multi-tenant hosts, variable reliability
A17: Thunder Compute | B17: Marketplace | C17: 1.4 | D17: 0.78 | E17: — | F17: — | G17: =IF(ISNUMBER(C17),C17*$B$4,"—") -> 12264 | H17: Lowest on-demand H100 class
A18: Spheron | B18: Marketplace | C18: 2.01 | D18: 1.2 | E18: — | F18: 1.03 | G18: =IF(ISNUMBER(C18),C18*$B$4,"—") -> 17607.6 | H18: Spot suits checkpointed batch jobs (fits 8h SLA)
A19: SR2-003 model assumption | B19: Reserved | C19: 2.75 | D19: 2.2 | E19: 1.8 | F19: — | G19: =C19*$B$4 -> 24090 | H19: Mid-market reserved rate used in the TCO model — consistent with specialist tier
A21: Residency: a rented GPU keeps data in YOUR VM (better than an API) but is still third-party infra — satisfies 'data in Canada' if region-pinned (AWS/Azure/GCP/OVH CA), NOT a strict 'on-premises only' clause. Watch hyperscaler egress ($0.08–0.12/GB); most specialists waive it. Spot = 50–70% cheaper but interruptible.

Sheet GPU_Sizing
A1: GPU sizing & sustained throughput (AC #1)
A2: Docs/day/set = out tok/s × 3600 × SLA hrs × utilisation ÷ output tok/doc. Estimates only — load-test before capex.
A4: Model / GPU set | B4: GPUs | C4: Out tok/s | D4: Docs/hour/set | E4: Docs/day/set | F4: Util @ Pilot | G4: Util @ Production | H4: Util @ Scale
A5: =Assumptions!A35 -> Llama-3.1-8B (1× L40S, fp16) | B5: =Assumptions!C35 -> 1 | C5: =Assumptions!D35 -> 3000 | D5: =C5*3600*Assumptions!$B$18/Assumptions!$B$13 -> 4320 | E5: =D5*Assumptions!$B$17 -> 34560 | F5: =Assumptions!B5/E5 -> 0.0028935185 | G5: =Assumptions!B6/E5 -> 0.014467593 | H5: =Assumptions!B7/E5 -> 0.05787037
A6: =Assumptions!A36 -> Mistral-Small-24B (1× H100) | B6: =Assumptions!C36 -> 1 | C6: =Assumptions!D36 -> 2200 | D6: =C6*3600*Assumptions!$B$18/Assumptions!$B$13 -> 3168 | E6: =D6*Assumptions!$B$17 -> 25344 | F6: =Assumptions!B5/E6 -> 0.0039457071 | G6: =Assumptions!B6/E6 -> 0.019728535 | H6: =Assumptions!B7/E6 -> 0.078914141
A7: =Assumptions!A37 -> Llama-3.3-70B (1× H100, AWQ 4-bit) | B7: =Assumptions!C37 -> 1 | C7: =Assumptions!D37 -> 1500 | D7: =C7*3600*Assumptions!$B$18/Assumptions!$B$13 -> 2160 | E7: =D7*Assumptions!$B$17 -> 17280 | F7: =Assumptions!B5/E7 -> 0.005787037 | G7: =Assumptions!B6/E7 -> 0.028935185 | H7: =Assumptions!B7/E7 -> 0.11574074
A8: =Assumptions!A38 -> Llama-3.3-70B (2× A100, TP2 fp16) | B8: =Assumptions!C38 -> 2 | C8: =Assumptions!D38 -> 1200 | D8: =C8*3600*Assumptions!$B$18/Assumptions!$B$13 -> 1728 | E8: =D8*Assumptions!$B$17 -> 13824 | F8: =Assumptions!B5/E8 -> 0.0072337963 | G8: =Assumptions!B6/E8 -> 0.036168981 | H8: =Assumptions!B7/E8 -> 0.14467593
A9: =Assumptions!A39 -> Cohere Command-A/R+ (4× A100) | B9: =Assumptions!C39 -> 4 | C9: =Assumptions!D39 -> 900 | D9: =C9*3600*Assumptions!$B$18/Assumptions!$B$13 -> 1296 | E9: =D9*Assumptions!$B$17 -> 10368 | F9: =Assumptions!B5/E9 -> 0.0096450617 | G9: =Assumptions!B6/E9 -> 0.048225309 | H9: =Assumptions!B7/E9 -> 0.19290123

Sheet SelfHost_Llama_8B
A1: Self-hosted Llama-3.1-8B — 1× L40S 48GB (fp16, vLLM)
A2: Cheapest self-host tier. Accuracy est. ~60–72% strict — likely below requirement; verify with accuracy_spotcheck/ before relying on it.
A4: Config | B4: =Assumptions!A35 -> Llama-3.1-8B (1× L40S, fp16)
A5: # GPUs | B5: =Assumptions!C35 -> 1
A6: GPU unit price ($) | B6: =INDEX(Assumptions!$B$29:$B$31,Assumptions!B35-28) -> 12000
A7: Watts/GPU | B7: =INDEX(Assumptions!$C$29:$C$31,Assumptions!B35-28) -> 350
A8: Rental $/hr/GPU | B8: =INDEX(Assumptions!$D$29:$D$31,Assumptions!B35-28) -> 1.8
A9: Docs/day capacity | B9: =Assumptions!D35*3600*Assumptions!$B$18*Assumptions!$B$17/Assumptions!$B$13 -> 34560
A11: ANNUAL COST — ON-PREM (capex amortised) vs CLOUD-RENTED GPU (reserved 24×7)
A12: Line item | B12: On-prem $/yr | C12: Cloud-rented $/yr | E12: Formula basis
A13: GPU capex (amortised) / rental | B13: =B6*B5/Assumptions!$B$21 -> 4000 | C13: =B8*B5*Assumptions!$B$24 -> 15768 | E13: price×n÷amort | $/hr×n×8760
A14: Power (incl. PUE) | B14: =B7*B5*Assumptions!$B$23*Assumptions!$B$24*Assumptions!$B$22/1000 -> 459.9 | C14: 0 | E14: W×n×PUE×8760×$/kWh÷1000 (rental includes power)
A15: Licensing | B15: =0 -> 0 | C15: =0 -> 0
A16: TOTAL / yr | B16: =SUM(B13:B15) -> 4459.9 | C16: =SUM(C13:C15) -> 15768
A18: COST PER DOC & UTILISATION BY VOLUME SCENARIO (fixed cost ÷ volume)
A19: Scenario | B19: Docs/year | C19: $/doc (on-prem) | D19: $/doc (rented) | E19: Capacity utilisation
A20: Pilot (100/day) | B20: =Assumptions!C5 -> 26000 | C20: =$B$16/B20 -> 0.17153462 | D20: =$C$16/B20 -> 0.60646154 | E20: =Assumptions!B5/$B$9 -> 0.0028935185
A21: Production (500/day) | B21: =Assumptions!C6 -> 130000 | C21: =$B$16/B21 -> 0.034306923 | D21: =$C$16/B21 -> 0.12129231 | E21: =Assumptions!B6/$B$9 -> 0.014467593
A22: Scale (2,000/day) | B22: =Assumptions!C7 -> 520000 | C22: =$B$16/B22 -> 0.0085767308 | D22: =$C$16/B22 -> 0.030323077 | E22: =Assumptions!B7/$B$9 -> 0.05787037

Sheet SelfHost_Mistral_24B
A1: Self-hosted Mistral-Small-24B — 1× H100 80GB (vLLM)
A2: Mid-tier open model; Apache-2.0 licence, strong structured-output behaviour for its size.
A4: Config | B4: =Assumptions!A36 -> Mistral-Small-24B (1× H100)
A5: # GPUs | B5: =Assumptions!C36 -> 1
A6: GPU unit price ($) | B6: =INDEX(Assumptions!$B$29:$B$31,Assumptions!B36-28) -> 32000
A7: Watts/GPU | B7: =INDEX(Assumptions!$C$29:$C$31,Assumptions!B36-28) -> 700
A8: Rental $/hr/GPU | B8: =INDEX(Assumptions!$D$29:$D$31,Assumptions!B36-28) -> 2.75
A9: Docs/day capacity | B9: =Assumptions!D36*3600*Assumptions!$B$18*Assumptions!$B$17/Assumptions!$B$13 -> 25344
A11: ANNUAL COST — ON-PREM (capex amortised) vs CLOUD-RENTED GPU (reserved 24×7)
A12: Line item | B12: On-prem $/yr | C12: Cloud-rented $/yr | E12: Formula basis
A13: GPU capex (amortised) / rental | B13: =B6*B5/Assumptions!$B$21 -> 10666.667 | C13: =B8*B5*Assumptions!$B$24 -> 24090 | E13: price×n÷amort | $/hr×n×8760
A14: Power (incl. PUE) | B14: =B7*B5*Assumptions!$B$23*Assumptions!$B$24*Assumptions!$B$22/1000 -> 919.8 | C14: 0 | E14: W×n×PUE×8760×$/kWh÷1000 (rental includes power)
A15: Licensing | B15: =0 -> 0 | C15: =0 -> 0
A16: TOTAL / yr | B16: =SUM(B13:B15) -> 11586.467 | C16: =SUM(C13:C15) -> 24090
A18: COST PER DOC & UTILISATION BY VOLUME SCENARIO (fixed cost ÷ volume)
A19: Scenario | B19: Docs/year | C19: $/doc (on-prem) | D19: $/doc (rented) | E19: Capacity utilisation
A20: Pilot (100/day) | B20: =Assumptions!C5 -> 26000 | C20: =$B$16/B20 -> 0.44563333 | D20: =$C$16/B20 -> 0.92653846 | E20: =Assumptions!B5/$B$9 -> 0.0039457071
A21: Production (500/day) | B21: =Assumptions!C6 -> 130000 | C21: =$B$16/B21 -> 0.089126667 | D21: =$C$16/B21 -> 0.18530769 | E21: =Assumptions!B6/$B$9 -> 0.019728535
A22: Scale (2,000/day) | B22: =Assumptions!C7 -> 520000 | C22: =$B$16/B22 -> 0.022281667 | D22: =$C$16/B22 -> 0.046326923 | E22: =Assumptions!B7/$B$9 -> 0.078914141

Sheet SelfHost_Llama_70B
A1: Self-hosted Llama-3.3-70B — 1× H100 (AWQ 4-bit) — recommended self-host config
A2: Est. ~82–90% strict on header fields (class-level estimate — verify with accuracy_spotcheck/). Alternative: 2× A100 80GB TP2 fp16 (see Assumptions row 38; ~$54.4k/yr on-prem incl. FTE). Qwen2.5-72B is a drop-in alternative.
A4: Config | B4: =Assumptions!A37 -> Llama-3.3-70B (1× H100, AWQ 4-bit)
A5: # GPUs | B5: =Assumptions!C37 -> 1
A6: GPU unit price ($) | B6: =INDEX(Assumptions!$B$29:$B$31,Assumptions!B37-28) -> 32000
A7: Watts/GPU | B7: =INDEX(Assumptions!$C$29:$C$31,Assumptions!B37-28) -> 700
A8: Rental $/hr/GPU | B8: =INDEX(Assumptions!$D$29:$D$31,Assumptions!B37-28) -> 2.75
A9: Docs/day capacity | B9: =Assumptions!D37*3600*Assumptions!$B$18*Assumptions!$B$17/Assumptions!$B$13 -> 17280
A11: ANNUAL COST — ON-PREM (capex amortised) vs CLOUD-RENTED GPU (reserved 24×7)
A12: Line item | B12: On-prem $/yr | C12: Cloud-rented $/yr | E12: Formula basis
A13: GPU capex (amortised) / rental | B13: =B6*B5/Assumptions!$B$21 -> 10666.667 | C13: =B8*B5*Assumptions!$B$24 -> 24090 | E13: price×n÷amort | $/hr×n×8760
A14: Power (incl. PUE) | B14: =B7*B5*Assumptions!$B$23*Assumptions!$B$24*Assumptions!$B$22/1000 -> 919.8 | C14: 0 | E14: W×n×PUE×8760×$/kWh÷1000 (rental includes power)
A15: Licensing | B15: =0 -> 0 | C15: =0 -> 0
A16: TOTAL / yr | B16: =SUM(B13:B15) -> 11586.467 | C16: =SUM(C13:C15) -> 24090
A18: COST PER DOC & UTILISATION BY VOLUME SCENARIO (fixed cost ÷ volume)
A19: Scenario | B19: Docs/year | C19: $/doc (on-prem) | D19: $/doc (rented) | E19: Capacity utilisation
A20: Pilot (100/day) | B20: =Assumptions!C5 -> 26000 | C20: =$B$16/B20 -> 0.44563333 | D20: =$C$16/B20 -> 0.92653846 | E20: =Assumptions!B5/$B$9 -> 0.005787037
A21: Production (500/day) | B21: =Assumptions!C6 -> 130000 | C21: =$B$16/B21 -> 0.089126667 | D21: =$C$16/B21 -> 0.18530769 | E21: =Assumptions!B6/$B$9 -> 0.028935185
A22: Scale (2,000/day) | B22: =Assumptions!C7 -> 520000 | C22: =$B$16/B22 -> 0.022281667 | D22: =$C$16/B22 -> 0.046326923 | E22: =Assumptions!B7/$B$9 -> 0.11574074

Sheet Cohere_Private
A1: Cohere Command-A/R+ private deployment — 4× A100 80GB + vendor licence
A2: Vendor-supported (lower FTE share) but licence PLACEHOLDER $150k/yr dominates TCO — get a real quote. Justify only if vendor SLA/support is required.
A4: Config | B4: =Assumptions!A39 -> Cohere Command-A/R+ (4× A100)
A5: # GPUs | B5: =Assumptions!C39 -> 4
A6: GPU unit price ($) | B6: =INDEX(Assumptions!$B$29:$B$31,Assumptions!B39-28) -> 20000
A7: Watts/GPU | B7: =INDEX(Assumptions!$C$29:$C$31,Assumptions!B39-28) -> 400
A8: Rental $/hr/GPU | B8: =INDEX(Assumptions!$D$29:$D$31,Assumptions!B39-28) -> 2.2
A9: Docs/day capacity | B9: =Assumptions!D39*3600*Assumptions!$B$18*Assumptions!$B$17/Assumptions!$B$13 -> 10368
A11: ANNUAL COST — ON-PREM (capex amortised) vs CLOUD-RENTED GPU (reserved 24×7)
A12: Line item | B12: On-prem $/yr | C12: Cloud-rented $/yr | E12: Formula basis
A13: GPU capex (amortised) / rental | B13: =B6*B5/Assumptions!$B$21 -> 26666.667 | C13: =B8*B5*Assumptions!$B$24 -> 77088 | E13: price×n÷amort | $/hr×n×8760
A14: Power (incl. PUE) | B14: =B7*B5*Assumptions!$B$23*Assumptions!$B$24*Assumptions!$B$22/1000 -> 2102.4 | C14: 0 | E14: W×n×PUE×8760×$/kWh÷1000 (rental includes power)
A15: Licensing | B15: =Assumptions!$B$42 -> 150000 | C15: =Assumptions!$B$42 -> 150000
A16: TOTAL / yr | B16: =SUM(B13:B15) -> 178769.07 | C16: =SUM(C13:C15) -> 227088
A18: COST PER DOC & UTILISATION BY VOLUME SCENARIO (fixed cost ÷ volume)
A19: Scenario | B19: Docs/year | C19: $/doc (on-prem) | D19: $/doc (rented) | E19: Capacity utilisation
A20: Pilot (100/day) | B20: =Assumptions!C5 -> 26000 | C20: =$B$16/B20 -> 6.8757333 | D20: =$C$16/B20 -> 8.7341538 | E20: =Assumptions!B5/$B$9 -> 0.0096450617
A21: Production (500/day) | B21: =Assumptions!C6 -> 130000 | C21: =$B$16/B21 -> 1.3751467 | D21: =$C$16/B21 -> 1.7468308 | E21: =Assumptions!B6/$B$9 -> 0.048225309
A22: Scale (2,000/day) | B22: =Assumptions!C7 -> 520000 | C22: =$B$16/B22 -> 0.34378667 | D22: =$C$16/B22 -> 0.43670769 | E22: =Assumptions!B7/$B$9 -> 0.19290123

Sheet OCR_AWS_Textract
A1: AWS Textract — Forms + Tables + Queries
A3: $/page | B3: =Assumptions!B46 -> 0.065
A5: Scenario | B5: Docs/year | C5: Pages/year | D5: Annual OCR cost
A6: Pilot (100/day) | B6: =Assumptions!C5 -> 26000 | C6: =B6*Assumptions!$B$14 -> 78000 | D6: =C6*$B$3 -> 5070
A7: Production (500/day) | B7: =Assumptions!C6 -> 130000 | C7: =B7*Assumptions!$B$14 -> 390000 | D7: =C7*$B$3 -> 25350
A8: Scale (2,000/day) | B8: =Assumptions!C7 -> 520000 | C8: =B8*Assumptions!$B$14 -> 1560000 | D8: =C8*$B$3 -> 101400
A10: Data egress: YES — pages leave the network. Breaks a strict residency mandate even if the LLM is self-hosted.
A12: Notes | B12: Best-in-class key-value/table extraction on forms; Queries API lets you ask for specific fields directly. Most expensive cloud OCR. Pricing tiers by feature (Detect vs Forms vs Tables vs Queries) — $0.065/pg models Forms+Tables class usage; verify against the AWS calculator for your feature mix.

Sheet OCR_GCP_DocAI
A1: GCP Document AI — Form Parser / custom processors
A3: $/page | B3: =Assumptions!B47 -> 0.03
A5: Scenario | B5: Docs/year | C5: Pages/year | D5: Annual OCR cost
A6: Pilot (100/day) | B6: =Assumptions!C5 -> 26000 | C6: =B6*Assumptions!$B$14 -> 78000 | D6: =C6*$B$3 -> 2340
A7: Production (500/day) | B7: =Assumptions!C6 -> 130000 | C7: =B7*Assumptions!$B$14 -> 390000 | D7: =C7*$B$3 -> 11700
A8: Scale (2,000/day) | B8: =Assumptions!C7 -> 520000 | C8: =B8*Assumptions!$B$14 -> 1560000 | D8: =C8*$B$3 -> 46800
A10: Data egress: YES — pages leave the network. Breaks a strict residency mandate even if the LLM is self-hosted.
A12: Notes | B12: Strong middle option. Custom processors can be trained on Actlabs' own form layouts — best accuracy play if staying in cloud. Form Parser class pricing modelled at $0.030/pg; custom-processor pricing differs — check the GCP pricing page.

Sheet OCR_Azure_DI
A1: Azure AI Document Intelligence — Layout / custom models
A3: $/page | B3: =Assumptions!B48 -> 0.01
A5: Scenario | B5: Docs/year | C5: Pages/year | D5: Annual OCR cost
A6: Pilot (100/day) | B6: =Assumptions!C5 -> 26000 | C6: =B6*Assumptions!$B$14 -> 78000 | D6: =C6*$B$3 -> 780
A7: Production (500/day) | B7: =Assumptions!C6 -> 130000 | C7: =B7*Assumptions!$B$14 -> 390000 | D7: =C7*$B$3 -> 3900
A8: Scale (2,000/day) | B8: =Assumptions!C7 -> 520000 | C8: =B8*Assumptions!$B$14 -> 1560000 | D8: =C8*$B$3 -> 15600
A10: Data egress: YES — pages leave the network. Breaks a strict residency mandate even if the LLM is self-hosted.
A12: Notes | B12: Cheapest cloud OCR (~$0.010/pg Layout class) with a strong custom-model story (train on your labelled forms). Natural pairing with a cloud LLM if residency is handled contractually.

Sheet OCR_SelfHosted
A1: Self-hosted OCR — required for a strict data-residency deployment
A2: If the driver for self-hosting is residency, OCR must also be self-hosted — cloud OCR egresses the raw document and defeats the purpose.
A4: Option | B4: Cost | C4: Data residency | D4: Notes
A5: Tesseract | B5: $0 (CPU compute) | C5: On-prem | D5: Mature, free; weak on complex multi-column layout — acceptable baseline only.
A6: PaddleOCR / docTR / Surya | B6: $0 (GPU compute) | C6: On-prem | D6: Modern open-source stacks; good layout + table handling; GPU-accelerated. Marginal cost ≈ $0 when sharing the LLM GPU node (which is heavily under-utilised — see GPU_Sizing).
A7: VLM: Qwen2-VL / Llama-3.2-Vision | B7: GPU (shared node) | C7: On-prem | D7: Vision-language model does OCR AND field extraction in one pass — simplest residency architecture (page never leaves the box, one model to operate). Trade-off: harder to debug OCR errors separately; benchmark against Paddle/docTR + 70B pipeline on the gold set.

Sheet OCR_LLM_Pipeline
A1: Do you need an LLM with the OCR? — Pipeline architecture & cost (open-model variant: Llama / Cohere)
A2: OCR converts pixels → text/layout (what characters, where). The LLM converts text → the 41 canonical JSON fields (what the characters MEAN). Evidence both are needed: the regex baseline had the same OCR text and scored 23.9% strict — its failures (layout / field-bleed) are exactly what an LLM fixes. NOTE: API-served Llama/Cohere still egresses data like any cloud LLM — open weights only give residency when self-hosted.
A4: INPUTS (blue = editable)
A5: Pages/doc | B5: =Assumptions!B14 -> 3 | D5: LLM $/doc — Llama-3.3-70B serverless API (~$0.72/M, Bedrock class) | E5: 0.0054 | H5: 7,500 tok/doc × $0.72/M = $0.0054 — verify current Bedrock/Together rates
A6: Docs/year (Production 500/day) | B6: =Assumptions!C6 -> 130000 | D6: LLM $/doc — Cohere Command A API (~$2.50/$10 per M) | E6: 0.03 | H6: Cohere API is priced at full per-token rates (no batch-discount tier) — verify current rates
A7: Self-host VLM fixed cost/yr (70B-class node) | B7: =SelfHost_Llama_70B!B16 -> 11586.467 | D7: OCR $/pg — Azure Layout / GCP Form / Textract F+T | E7: 0.01 | F7: 0.03 | G7: 0.065
A9: ARCHITECTURE OPTIONS — cost per doc & annual (Production)
A10: Architecture | B10: Stages | C10: OCR $/doc | D10: LLM $/doc | E10: Total $/doc | F10: Accuracy (strict, est.) | G10: Annual | H10: Verdict / when to use
A11: A. OCR + LLM — RECOMMENDED cloud | B11: Azure DI Layout → Llama-3.3-70B (serverless API) | C11: =$E$7*$B$5 -> 0.03 | D11: =$E$5 -> 0.0054 | E11: =C11+D11 -> 0.0354 | F11: 0.86 | G11: =E11*$B$6 -> 4602 | H11: Default open-model stack. Cheap layout-OCR + cheap serverless LLM; debuggable intermediate text; low lock-in — same model can move on-prem later. Verify accuracy on the gold set before locking in.
A12: A2. OCR + LLM (managed-vendor variant) | B12: GCP Doc AI Form Parser → Cohere Command A (API) | C12: =$F$7*$B$5 -> 0.09 | D12: =$E$6 -> 0.03 | E12: =C12+D12 -> 0.12 | F12: 0.86 | G12: =E12*$B$6 -> 15600 | H12: If vendor support/SLA is preferred over open weights; ~same accuracy tier as Llama-70B at ~5× the LLM cost.
A13: B. OCR-only (no LLM) | B13: Textract Forms+Tables / GCP custom extractor | C13: =$F$7*$B$5 -> 0.09 | D13: 0 | E13: =C13+D13 -> 0.09 | F13: 0.6 | G13: =E13*$B$6 -> 11700 | H13: Key-value extraction only — no schema JSON, normalisation, or structured sub-objects. Plateaus on hard fields; spot-check a GCP custom extractor on the gold set if testing this path.
A14: C. VLM-only (one model, no separate OCR) | B14: Qwen2-VL / Llama-3.2-Vision, self-hosted | C14: 0 | D14: =$B$7/$B$6 -> 0.089126667 | E14: =C14+D14 -> 0.089126667 | F14: 0.86 | G14: =E14*$B$6 -> 11586.467 | H14: Simplest RESIDENCY architecture — page never leaves the box. Harder to debug OCR vs mapping errors. Cost = fixed node ÷ volume.
A15: D. Regex-only (SR2-002 baseline) | B15: OCR text → regex patterns | C15: =$E$7*$B$5 -> 0.03 | D15: 0 | E15: =C15+D15 -> 0.03 | F15: 0.239 | G15: =E15*$B$6 -> 3900 | H15: MEASURED 23.9%. Keep as fallback/pre-filter only — breaks on every layout variant.
A17: RECOMMENDATION (row A) — full rationale
A18: 1. OCR + LLM — Recommended | B18: Llama-3.3-70B via a serverless cloud API (AWS Bedrock / Together AI class, ~$0.72/M tok) at Production volume: ~$0.0054/doc → ~$700/yr LLM cost, fastest open-model path to stand up, zero GPU ops, expected accuracy ~82–90% strict est. vs 23.9% measured regex baseline — verify on the gold set before locking in. Pair with Azure Document Intelligence Layout or GCP Document AI custom processors for OCR. Caution: an API-served Llama still egresses data exactly like any cloud LLM — apply the same mitigations: ZDR / no-retention terms, region pinning (e.g. Bedrock ca-central-1 for Canada), DPA no-training terms, PII redaction, never transmit the PCI block. The open-weights advantage is low lock-in: the same model can later move on-prem unchanged if a residency mandate lands.
A20: DIVISION OF LABOUR — what each stage does
A21: Stage | B21: Answers | C21: Examples | H21: Cannot do
A22: OCR / layout (Azure DI, GCP, Paddle/docTR) | B22: What characters are on the page, and where? | C22: Text, tables, key-value regions, reading order on messy multi-column scans | H22: Doesn't know 'PO#' = 'Purchase Order', can't normalise units/dates, can't build the 41-field JSON
A23: LLM extraction (Llama-3.3-70B or Cohere Command A) | B23: What do the characters MEAN? | C23: Maps synonyms, resolves field-bleed, normalises values, emits schema-conformant JSON incl. reporting grid & disposition matrix | H23: Can't read pixels (needs OCR text) — unless it's a VLM (option C)
A25: Bottom line: yes — pair OCR with an LLM. Recommended open-model stack (A) lands ~$0.035/doc all-in (~$4.6k/yr at Production) at the 70B accuracy tier (~82–90% est.); the Cohere-API variant (A2) costs ~$0.12/doc for the same tier. OCR-only (B) is the only no-LLM path worth testing but plateaus below the LLM on hard fields. VLM-only (C) is reserved for the data-residency mandate.

Sheet TCO_Summary
A1: Three-year TCO — annualised, all options (AC #2)
A2: Green = links to technology tabs. Self-host totals include an MLOps FTE share (25% open / 15% Cohere). Fixed-cost dominated — barely moves with volume.
A4: Option | B4: Annual @ Pilot | C4: Annual @ Production | D4: Annual @ Scale | E4: × cheapest | F4: Basis
A5: Self-host Llama-3.1-8B (on-prem, 1× L40S) | B5: =SelfHost_Llama_8B!$B$16 -> 4459.9 | C5: =SelfHost_Llama_8B!$B$16 -> 4459.9 | D5: =SelfHost_Llama_8B!$B$16 -> 4459.9 | E5: =C5/MIN($C$5:$C$9) -> 1 | F5: fixed
A6: Self-host Mistral-Small-24B (on-prem, 1× H100) | B6: =SelfHost_Mistral_24B!$B$16 -> 11586.467 | C6: =SelfHost_Mistral_24B!$B$16 -> 11586.467 | D6: =SelfHost_Mistral_24B!$B$16 -> 11586.467 | E6: =C6/MIN($C$5:$C$9) -> 2.5979207 | F6: fixed
A7: Self-host Llama-3.3-70B (on-prem, 1× H100 AWQ) | B7: =SelfHost_Llama_70B!$B$16 -> 11586.467 | C7: =SelfHost_Llama_70B!$B$16 -> 11586.467 | D7: =SelfHost_Llama_70B!$B$16 -> 11586.467 | E7: =C7/MIN($C$5:$C$9) -> 2.5979207 | F7: fixed
A8: Cloud-rented H100 (Llama-70B, reserved 24×7) | B8: =SelfHost_Llama_70B!$C$16 -> 24090 | C8: =SelfHost_Llama_70B!$C$16 -> 24090 | D8: =SelfHost_Llama_70B!$C$16 -> 24090 | E8: =C8/MIN($C$5:$C$9) -> 5.4014664 | F8: fixed
A9: Cohere Command-A/R+ private (on-prem, 4× A100) | B9: =Cohere_Private!$B$16 -> 178769.07 | C9: =Cohere_Private!$B$16 -> 178769.07 | D9: =Cohere_Private!$B$16 -> 178769.07 | E9: =C9/MIN($C$5:$C$9) -> 40.083649 | F9: fixed; licence placeholder
A11: Cloud OCR add-on if outsourced (breaks residency)
A12: AWS Textract | B12: =OCR_AWS_Textract!D6 -> 5070 | C12: =OCR_AWS_Textract!D7 -> 25350 | D12: =OCR_AWS_Textract!D8 -> 101400
A13: GCP Document AI | B13: =OCR_GCP_DocAI!D6 -> 2340 | C13: =OCR_GCP_DocAI!D7 -> 11700 | D13: =OCR_GCP_DocAI!D8 -> 46800
A14: Azure Doc Intelligence | B14: =OCR_Azure_DI!D6 -> 780 | C14: =OCR_Azure_DI!D7 -> 3900 | D14: =OCR_Azure_DI!D8 -> 15600

Sheet Accuracy_SpotCheck
A1: Extraction accuracy — self-hosted vs cloud, on the SR2-002 gold set (AC #3)
A2: Metric: 14 fields / 167 instances over the 19-doc gold set, same OCR text as the regex baseline. YELLOW cells = class-level ESTIMATES — run accuracy_spotcheck/ on lab hardware and replace with measured numbers.
A4: Pipeline | B4: Strict (est.) | C4: Weighted (est.) | D4: Strict (measured) | E4: Weighted (measured) | F4: Status / notes
A5: Regex baseline (SR2-002, current code) | B5: n/a | C5: n/a | D5: =Assumptions!B51 -> 0.239 | E5: =Assumptions!B52 -> 0.317 | F5: MEASURED — failures almost entirely layout / field-bleed
A6: Self-host 8B (Llama-3.1 / Mistral) | B6: 0.66 | C6: 0.75 | F6: Estimate — run harness (range 60–72% / 70–80%)
A7: Self-host 70B (Llama-3.3 / Qwen2.5-72B) | B7: 0.86 | C7: 0.91 | F7: Estimate — run harness (range 82–90% / 88–94%)
A8: Cohere Command-A/R+ (private) | B8: 0.86 | C8: 0.91 | F8: Estimate — run harness (range 82–90% / 88–94%)
A10: Conclusion: a self-hosted 70B is expected to land in the ~82–90% strict band on header fields — accuracy does NOT decide self-host-vs-cloud; cost, residency and ops burden do. Structured Rev2.0 fields (reporting grid, disposition matrix, sign-off) will separate the tiers more — extend the scorer's field list to measure them explicitly.

Sheet Residency_Compliance
A1: Data-residency & compliance — the one place self-hosting wins decisively (AC #4)
A2: Forms carry client PII (names/emails/phones/addresses), commercial terms (quotes/PO/pricing), and PCI card data (dropped by policy — never persist).
A4: Benefit | B4: Self-hosted (on-prem / VPC) | C4: Cloud LLM API
A5: Data leaves premises | B5: No — stays in Actlabs network | C5: Yes — sent to provider
A6: Data residency (Canada / Ontario) | B6: Fully controlled | C6: Depends on provider region / DPA
A7: Training on your data | B7: Impossible (your weights, your infra) | C7: Contractually excluded — requires trust in Data Processing Agreement (DPA)
A8: PII / PC(Payment Card)I blast radius | B8: Contained to owned infra | C8: Extends to provider + subprocessors
A9: Audit / certification scope | B9: You control the boundary | C9: Rely on provider SOC2/ISO + Data Processing Agreement
A10: Client contractual 'no-cloud' clauses | B10: Satisfiable | C10: Not satisfiable
A12: CLOUD-SIDE MITIGATIONS THAT NARROW THE GAP (cheaper than self-hosting)
A13: • Zero-Data-Retention (ZDR) — prompts not stored by the provider
A14: • Region-pinned / data-residency deployment
A15: • Signed DPA with explicit no-training terms
A16: • PII redaction / tokenisation before send
A17: • Never transmit the PCI block (already policy)
A19: Egress warning: if cloud OCR is used 'just for OCR', data still egresses — a partial self-host does not satisfy a strict no-cloud mandate. Residency deployments must pair a self-hosted LLM with self-hosted OCR (PaddleOCR/docTR/Surya) or a VLM (Qwen2-VL / Llama-3.2-Vision).

Sheet Scoring_Matrix
A1: Weighted decision matrix (scores 1–5, 5 = best; blue = judgement inputs — adjust to your priorities)
A3: Criterion | B3: Weight | C3: Python regex only (SR2-002) | D3: Self-host 8B on-prem | E3: Self-host 70B on-prem | F3: Cohere private
A4: Accuracy (gold set) | B4: 0.25 | C4: 1 | D4: 2 | E4: 4 | F4: 4
A5: $/doc | B5: 0.15 | C5: 5 | D5: 2 | E5: 2 | F5: 1
A6: Annual TCO | B6: 0.1 | C6: 5 | D6: 3 | E6: 3 | F6: 1
A7: Latency / SLA fit | B7: 0.1 | C7: 5 | D7: 4 | E7: 4 | F7: 4
A8: Data residency / compliance | B8: 0.2 | C8: 5 | D8: 5 | E8: 5 | F8: 5
A9: Maintenance burden | B9: 0.1 | C9: 2 | D9: 2 | E9: 2 | F9: 3
A10: Build effort (time-to-prod) | B10: 0.1 | C10: 4 | D10: 2 | E10: 2 | F10: 3
A11: Weight check | B11: =SUM(B4:B10) -> 1
A12: WEIGHTED SCORE | C12: =SUMPRODUCT($B$4:$B$10,C4:C10) -> 3.6 | D12: =SUMPRODUCT($B$4:$B$10,D4:D10) -> 2.9 | E12: =SUMPRODUCT($B$4:$B$10,E4:E10) -> 3.4 | F12: =SUMPRODUCT($B$4:$B$10,F4:F10) -> 3.25
A13: Rank | C13: =RANK(C12,$C$12:$F$12) -> 1 | D13: =RANK(D12,$C$12:$F$12) -> 4 | E13: =RANK(E12,$C$12:$F$12) -> 2 | F13: =RANK(F12,$C$12:$F$12) -> 3

Sheet Recommendation
A1: Recommendation — Cloud API vs on-prem vs Python-only
A3: 1. OCR+ LLM Recommeded | B3: Llama-3.3-70B served via a serverless cloud API (AWS Bedrock / Together AI class, ~$0.72/M tok) at Production volume — ~$0.0054/doc → ~$700/yr LLM cost, fastest open-model path to stand up, zero GPU ops, expected accuracy ~82–90% strict est. vs 23.9% measured regex baseline — verify on the gold set. Pair with Azure Document Intelligence Layout or GCP Document AI custom processors for OCR. Caution: an API-served Llama still egresses data exactly like any cloud LLM — apply the same mitigations: ZDR/no-retention terms, region pinning (e.g. Bedrock ca-central-1), DPA no-training terms, PII redaction, never transmit the PCI block. The open-weights advantage is low lock-in: the same model can later move on-prem unchanged if a residency mandate lands.
A4: 2. IF residency mandated: self-host 70B | B4: Only if a client contract or regulator requires lab data to stay on Actlabs infrastructure. Deploy Llama-3.3-70B (or Qwen2.5-72B) on a single H100 (AWQ 4-bit) PLUS self-hosted OCR (PaddleOCR/docTR/Surya) or a VLM (Qwen2-VL / Llama-3.2-Vision) so no page ever leaves the network. ~$50k/yr, near-cloud accuracy expected, full residency. Prefer Cohere private only if vendor support/SLA is required AND the negotiated licence justifies ~$200k/yr.
A5: 3. NOT recommended: Python/regex only | B5: Keep as fallback/pre-filter only. Measured 23.9% strict / 31.7% weighted — failures are structural (layout / field-bleed), and regex maintenance grows with every form variant. It scores last on the Scoring_Matrix despite being free.
A6: Before committing (either path) | B6: (a) Get the real intake volume and update Assumptions!B5:B7 — the whole model recalculates. (b) Run accuracy_spotcheck/ on candidate models and paste measured numbers into Accuracy_SpotCheck columns D:E. (c) Get a real Cohere quote to replace the $150k placeholder (Assumptions!B42). (d) Load-test vLLM throughput before any GPU purchase (±40% risk).

Sheet Pricing_References
A1: Pricing references & sources
A3: Item | B3: Value used | C3: Source / where to verify
A4: AWS Textract ~$0.065/pg (Forms+Tables class) | B4: Assumptions!B46 | C4: https://aws.amazon.com/textract/pricing/ — tiered by feature; use AWS calculator for your mix
A5: GCP Document AI ~$0.030/pg (Form Parser class) | B5: Assumptions!B47 | C5: https://cloud.google.com/document-ai/pricing — custom processors priced differently
A6: Azure AI Document Intelligence ~$0.010/pg (Layout class) | B6: Assumptions!B48 | C6: https://azure.microsoft.com/pricing/details/ai-document-intelligence/
A7: GPU street prices: L40S $12k / H100 $32k / A100-80GB $20k | B7: Assumptions!B29:B31 | C7: Mid-2026 street-price class figures — replace with vendor quotes
A8: GPU reserved rental: L40S $1.80 / H100 $2.75 / A100 $2.20 per hr | B8: Assumptions!D29:D31 | C8: Reserved cloud-GPU class rates (CoreWeave/Lambda/AWS class) — verify per provider
A9: Cohere private-deployment licence $150k/yr | B9: Assumptions!B42 | C9: PLACEHOLDER — negotiated per contract, not public; contact Cohere sales
A10: MLOps FTE $160k loaded; 25% (open) / 15% (Cohere) | B10: Assumptions!B55:B57 | C10: Internal estimate — optimistic for a team new to GPU serving
A11: Power $0.10/kWh, PUE 1.5, 3-yr amortisation | B11: Assumptions!B21:B23 | C11: Internal facilities assumption
A12: vLLM throughput estimates (900–3,000 out tok/s) | B12: Assumptions!D35:D39 | C12: Order-of-magnitude batched-serving estimates — confirm with load test (±40%)
A13: Regex baseline 23.9% strict / 31.7% weighted | B13: Assumptions!B51:B52 | C13: MEASURED — SR2-002 scorecard, 19-doc gold set, 14 fields / 167 instances
A14: Open-model licences | B14: n/a | C14: Llama 3.x: Meta community licence · Mistral-Small-24B: Apache-2.0 · Qwen2.5: Apache-2.0 (check 72B variant terms)
